Workbook

Sheet INVENTARIO JULIO 
A3: Inventario Inicial/Final Tiendas | F3: Inventario Inicial/Final Almacenes de Cendis
A4: Almacen | B4: Valor Inicial | C4: Valor Final | F4: Almacen | G4: Valor Inicial | H4: Valor Final
A5: ACB/Existencias | B5: 49023.84 | C5: 39729.41 | F5: CTDD/Existencias | G5: 1245467.6 | H5: 1635382.9 | I5: CENTRO DE DISTRIBUCION (BULTO CERRADO)
A6: ACG/Existencias | B6: 47200.37 | C6: 40562.12 | F6: CENSWM/Existencias | G6: 43153.63 | H6: 45844.31 | I6: SHOW ROOM
A7: ACO/Existencias | B7: 64130.41 | C7: 72396.54 | F7: EVENC/Existencias | G7: 14342.95 | H7: 15056.99 | I7: EVENTOS
A8: ADO/Existencias | B8: 46414.04 | C8: 46940.82 | F8: FARMA/Existencias | G8: 23427.75 | H8: 28833.02 | I8: FARMATODO
A9: ADS - TCY/Existencias | B9: 59025.22 | C9: 54097.42 | F9: GECOM/Existencias | G9: 19.14 | H9: 0
A10: ANT/Existencias | B10: 61641.29 | C10: 51455.89 | F10: ICDD/Existencias | G10: 538868.8 | H10: 416831.92 | I10: INSUMOS
A11: APU/Existencias | B11: 55092.81 | C11: 62230.8 | F11: MIXTO/Existencias | G11: 578017.9 | H11: 595224.93 | I11: ZONA MIXTA
A12: ARO - INT/Existencias | B12: 0 | C12: 0 | F12: MTA/Existencias | G12: 193641.43 | H12: 849946.04 | I12: MATERIA PRIMA
A13: ARO - NAC/Existencias | B13: 0 | C13: 0 | F13: SUM/Existencias | G13: 994.26 | H13: 967.93 | I13: REDES
A14: ATV/Existencias | B14: 40831.93 | C14: 41135.18 | F14: DEVVENEZ/Existencias | G14: 23365.79 | H14: 117251.43 | I14: DEVOLUCIONES
A15: AVM/Existencias | B15: 25361.18 | C15: 29877.56 | F15: PCRTI/Existencias | G15: 65708.4 | H15: 65359.7
A16: BAC/Existencias | B16: 41408.77 | C16: 35083.37 | F16: TI-CENDIS/Existencias | G16: 96.79 | H16: 4616.78
A17: BCC/Existencias | B17: 56729.44 | C17: 48350.95 | F17: PICK/Existencias | G17: 798474.51 | H17: 932148.66 | I17: PICKING VARIEDAD DE MERCANCIA
A18: BCD/Existencias | B18: 35401.29 | C18: 31794.64 | F18: VMC /Existencias | G18: 997.96 | H18: 862.24 | I18: CHUCHERIAS
A19: BCN/Existencias | B19: 53754.66 | C19: 51746.29 | F19: CEN - MYR/Existencias | G19: 176.6 | H19: -320.46
A20: BCO/Existencias | B20: 40650.95 | C20: 45999.82 | F20: Totales | G20: =SUM(G5:G19) -> 3526753.6 | H20: =SUM(H5:H19) -> 4708006.4
A21: BJM/Existencias | B21: 52190.32 | C21: 51828.39
A22: BLS /Existencias | B22: 0 | C22: 38029.82
A23: BNS/Existencias | B23: 89752.63 | C23: 79186.7
A24: BRC/Existencias | B24: 36692.63 | C24: 47018.23 | F24: Venez/Existencias | G24: 13400.92 | H24: -149722.8
A25: BTA/Existencias | B25: 60108.49 | C25: 43181.87
A26: BVC/Existencias | B26: 90014.11 | C26: 66192.63 | F26: Total almacenes cendis | G26: =G24+G20 -> 3540154.5 | H26: =H24+H20 -> 4558283.6
A27: BZC/Existencias | B27: 37568.43 | C27: 34535.52
A28: BZD/Existencias | B28: 54697.45 | C28: 62895.26
A29: BZT/Existencias | B29: 35239.69 | C29: 34550.52
A30: BZU/Existencias | B30: 40397.51 | C30: 38736.61
A31: CAG/Existencias | B31: 39194.46 | C31: 34749.9
A32: CAT/Existencias | B32: 101322.83 | C32: 92309.46
A33: CBM/Existencias | B33: 58012.13 | C33: 70389
A34: CBQ/Existencias | B34: 60140.37 | C34: 63475.85
A35: CBR/Existencias | B35: 44760.36 | C35: 38903.25
A36: CBV/Existencias | B36: 59311.17 | C36: 57708.45
A37: CCA/Existencias | B37: 61838.12 | C37: 44466.35
A38: CCB/Existencias | B38: 45461.46 | C38: 35402.43
... A226: ZAR/Existencias | B226: 55946.11 | C226: 47828.13
A227: Total general | B227: =SUM(B5:B226) -> 10949399 | C227: =SUM(C5:C226) -> 9767525.9

Sheet INV GARANTIAS JULIO
A2: Garantias Inicial/Final Tiendas | E2: Garantias Inicial/Final Almacenes de Cendis
A3: Almacen | B3: Valor Inicial | C3: Valor Final | E3: Almacen | F3: Valor Inicial | G3: Valor Final
A4: ABM-GAR/Existencias | B4: 149.62 | C4: 488.85 | E4: CEN-GAR/Control de calidad | F4: 78.14 | G4: 0
A5: ABM-GAR/Existencias/Existencias | B5: -29.71 | C5: -31.83 | E5: CEN-GAR/Entrada | F5: 756.86 | G5: 0
A6: ACB-GAR/Existencias | B6: 588.07 | C6: 161.21 | E6: CEN-GAR/Existencias | F6: 135534.27 | G6: 204546.68
A7: ACG-GAR/Existencias | B7: 166.78 | C7: 11.85 | E7: CEN-GAR/PosproducciÃ³n | F7: 121.44 | G7: 0
A8: ACO-GAR/Existencias | B8: 781.18 | C8: 397.9 | E8: CENSWM-GAR/Existencias | F8: 0 | G8: 0.25
A9: ADO-GAR/Existencias | B9: 0 | C9: 217.52 | E9: Totales | F9: =SUM(F4:F8) -> 136490.71 | G9: =SUM(G4:G8) -> 204546.93
A10: ADSTCY-GAR/Existencias | B10: 23.09 | C10: 8.32
A11: ANT-GAR/Existencias | B11: 64.1 | C11: 65.1
A12: APU-GAR/Existencias | B12: 532.4 | C12: -69.19
A13: AROINT-GAR/Existencias | B13: -18.34 | C13: 0
A14: ARONAC-GAR/Existencias | B14: -29.75 | C14: 0
A15: ATV-GAR/Existencias | B15: 154.72 | C15: 0
A16: AVM-GAR/Existencias | B16: 126.32 | C16: 102.45
A17: BAC-GAR/Existencias | B17: 0 | C17: 640.31
A18: BCC-GAR/Existencias | B18: 477.82 | C18: 71.7
A19: BCD-GAR/Existencias | B19: 470.33 | C19: 60.23
A20: BCN-GAR/Existencias | B20: 58.93 | C20: 11.96
A21: BCO-GAR/Existencias | B21: 194.94 | C21: 178.56
... A212: ZAR-GAR/Existencias | B212: 253.6 | C212: 622.68
A213: Totales | B213: =SUM(B4:B212) -> 60619.1 | C213: =SUM(C4:C212) -> 51480.3

Sheet EDR JULIO
A1: Centros de Costos | B1: Gastos | C1: Costos | D1: Ingresos | E1: Otros Ingresos | F1: Total de ingresos | G1: Total general
A2: [ ABM ] - AV BOLIVAR DE MATURIN | B2: 391.179 | F2: =SUM(D2,E2) -> 0 | G2: =B2+C2+D2+E2 -> 391.179 | H2: =IFERROR(C2/F2,0%) -> 0
A3: [ ACB ] - AV LIBERTADOR CIUDAD BOLIVAR | B3: 9865.879 | C3: 22717.278 | D3: -42850.541 | E3: -6262.729 | F3: =SUM(D3,E3) -> -49113.27 | G3: =B3+C3+D3+E3 -> -16530.113 | H3: =IFERROR(C3/F3,0%) -> -0.46254868
A4: [ ACG ] - ACHAGUAS | B4: 4713.688 | C4: 29078.434 | D4: -49631.89 | E4: -7309.932 | F4: =SUM(D4,E4) -> -56941.822 | G4: =B4+C4+D4+E4 -> -23149.7 | H4: =IFERROR(C4/F4,0%) -> -0.51066919
A5: [ ACO ] - ANACO | B5: 7403.344 | C5: 60262.727 | D5: -104454 | E5: -14443.039 | F5: =SUM(D5,E5) -> -118897.04 | G5: =B5+C5+D5+E5 -> -51230.972 | H5: =IFERROR(C5/F5,0%) -> -0.50684799
A6: [ ADO ] - ALTAGRACIA DEL ORITUCO | B6: 5414.652 | C6: 41163.746 | D6: -73293.141 | E6: -10855.169 | F6: =SUM(D6,E6) -> -84148.31 | G6: =B6+C6+D6+E6 -> -37569.912 | H6: =IFERROR(C6/F6,0%) -> -0.4891809
A7: [ ADS - BQT ] - AEDOS BARQUISIMETO | B7: -11.033 | F7: =SUM(D7,E7) -> 0 | G7: =B7+C7+D7+E7 -> -11.033 | H7: =IFERROR(C7/F7,0%) -> 0
A8: [ ADS - TCY ] - AEDOS TOCUYITO | B8: 25121.691 | C8: 6022.502 | D8: -17002.863 | E8: -2326.228 | F8: =SUM(D8,E8) -> -19329.091 | G8: =B8+C8+D8+E8 -> 11815.102 | H8: =IFERROR(C8/F8,0%) -> -0.31157709
A9: [ ANT ] - ANTIMANO | B9: 6722.854 | C9: 5543.328 | D9: -10027.621 | E9: -1473.34 | F9: =SUM(D9,E9) -> -11500.961 | G9: =B9+C9+D9+E9 -> 765.221 | H9: =IFERROR(C9/F9,0%) -> -0.48198824
A10: [ APU ] - APURE | B10: 7256.201 | C10: 49343.272 | D10: -81546.616 | E10: -12020.995 | F10: =SUM(D10,E10) -> -93567.611 | G10: =B10+C10+D10+E10 -> -36968.138 | H10: =IFERROR(C10/F10,0%) -> -0.52735419
A11: [ ARO - INT ] - AEROPUERTO INTERNACIONAL | B11: 1807.084 | C11: -181.214 | F11: =SUM(D11,E11) -> 0 | G11: =B11+C11+D11+E11 -> 1625.87 | H11: =IFERROR(C11/F11,0%) -> 0
A12: [ ARO - NAC ] - AEROPUERTO NACIONAL | B12: 2174.264 | C12: 7697.841 | F12: =SUM(D12,E12) -> 0 | G12: =B12+C12+D12+E12 -> 9872.105 | H12: =IFERROR(C12/F12,0%) -> 0
A13: [ ARY ] - AROA YARACUY | B13: 16.62 | C13: -32.068 | F13: =SUM(D13,E13) -> 0 | G13: =B13+C13+D13+E13 -> -15.448 | H13: =IFERROR(C13/F13,0%) -> 0
A14: [ ATV ] - ALTA VISTA | B14: 310.188 | C14: 18339.91 | D14: -35063.775 | E14: -5058.827 | F14: =SUM(D14,E14) -> -40122.602 | G14: =B14+C14+D14+E14 -> -21472.504 | H14: =IFERROR(C14/F14,0%) -> -0.45709673
A15: [ AVM ] - AVENIDA MARIÑO | B15: 4065.688 | C15: 24877.791 | D15: -44264.45 | F15: =SUM(D15,E15) -> -44264.45 | G15: =B15+C15+D15+E15 -> -15320.971 | H15: =IFERROR(C15/F15,0%) -> -0.56202643
A16: [ BAC ] - BUENOS AIRES CANGURO | B16: 5359.375 | C16: 22589.678 | D16: -39774.96 | E16: -5408.154 | F16: =SUM(D16,E16) -> -45183.114 | G16: =B16+C16+D16+E16 -> -17234.061 | H16: =IFERROR(C16/F16,0%) -> -0.49995841
A17: [ BCC ] - BISCUCUY | B17: 8264.593 | C17: 17173.338 | D17: -28714.826 | E17: -4288.169 | F17: =SUM(D17,E17) -> -33002.995 | G17: =B17+C17+D17+E17 -> -7565.064 | H17: =IFERROR(C17/F17,0%) -> -0.52035696
A18: [ BCD ] - BARINAS CC DORADO | B18: 3561.329 | C18: 16467.36 | D18: -28423.281 | E18: -4072.416 | F18: =SUM(D18,E18) -> -32495.697 | G18: =B18+C18+D18+E18 -> -12467.008 | H18: =IFERROR(C18/F18,0%) -> -0.50675509
A19: [ BCN ] - BARCELONA | B19: 7330.502 | C19: 38567.289 | D19: -69454.678 | E19: -9945.594 | F19: =SUM(D19,E19) -> -79400.272 | G19: =B19+C19+D19+E19 -> -33502.481 | H19: =IFERROR(C19/F19,0%) -> -0.48573245
A20: [ BCO ] - BOCONO | B20: 6102.949 | C20: 23941.996 | D20: -42456.901 | E20: -5997.832 | F20: =SUM(D20,E20) -> -48454.733 | G20: =B20+C20+D20+E20 -> -18409.788 | H20: =IFERROR(C20/F20,0%) -> -0.49411058
A21: [ BJM ] - BEJUMA | B21: 6610.181 | C21: 24201.919 | D21: -42637.384 | E21: -6002.81 | F21: =SUM(D21,E21) -> -48640.194 | G21: =B21+C21+D21+E21 -> -17828.094 | H21: =IFERROR(C21/F21,0%) -> -0.49757036
A22: [ BLS ] - BAILADORES | B22: 784.006 | C22: 815.361 | D22: -2366.67 | E22: -341.41 | F22: =SUM(D22,E22) -> -2708.08 | G22: =B22+C22+D22+E22 -> -1108.713 | H22: =IFERROR(C22/F22,0%) -> -0.30108453
A23: [ BNS ] - BARINAS SHOP | B23: 11196.559 | C23: 63765.986 | D23: -104268.82 | E23: -15267.428 | F23: =SUM(D23,E23) -> -119536.24 | G23: =B23+C23+D23+E23 -> -44573.699 | H23: =IFERROR(C23/F23,0%) -> -0.53344479
A24: [ BRC ] - BARRANCAS | B24: 4028.58 | C24: 19262.203 | D24: -33678.031 | E24: -4809.871 | F24: =SUM(D24,E24) -> -38487.902 | G24: =B24+C24+D24+E24 -> -15197.119 | H24: =IFERROR(C24/F24,0%) -> -0.50047423
A25: [ BTA ] - BARUTA | B25: 11531.063 | C25: 32236.414 | D25: -60104.394 | E25: -8934.499 | F25: =SUM(D25,E25) -> -69038.893 | G25: =B25+C25+D25+E25 -> -25271.416 | H25: =IFERROR(C25/F25,0%) -> -0.46693121
A26: [ BVC ] - BAZAR VALENCIA CANGURO | B26: 11074.405 | C26: 69758.571 | D26: -107646.38 | E26: -15914.072 | F26: =SUM(D26,E26) -> -123560.45 | G26: =B26+C26+D26+E26 -> -42727.477 | H26: =IFERROR(C26/F26,0%) -> -0.56457037
A27: [ BZC ] - BAZAR 4 | B27: 4805.209 | C27: 28294.648 | D27: -43041.202 | E27: -5823.708 | F27: =SUM(D27,E27) -> -48864.91 | G27: =B27+C27+D27+E27 -> -15765.053 | H27: =IFERROR(C27/F27,0%) -> -0.57903817
... A44: [ CEN - MYR ] - CENDIS MAYOR | B44: 808.31 | C44: 2363.826 | D44: -3726.185 | E44: -2149.48 | F44: =SUM(D44,E44) -> -5875.665 | G44: =B44+C44+D44+E44 -> -2703.529 | H44: =IFERROR(C44/F44,0%) -> -0.40230782
A45: [ CEN - SWM ] - CENDIS SHOWROOM | C45: 266.303 | D45: -1124.137 | E45: -177.379 | F45: =SUM(D45,E45) -> -1301.516 | G45: =B45+C45+D45+E45 -> -1035.213 | H45: =IFERROR(C45/F45,0%) -> -0.20460985
A46: [ CHA ] - CHACAO | B46: 5047.858 | C46: 19736.182 | D46: -42880.256 | E46: -6232.108 | F46: =SUM(D46,E46) -> -49112.364 | G46: =B46+C46+D46+E46 -> -24328.324 | H46: =IFERROR(C46/F46,0%) -> -0.40185771
A47: [ CHC ] - CHICHIRIVICHE | B47: 3995.675 | C47: 10575.546 | D47: -18154.255 | E47: -2724.352 | F47: =SUM(D47,E47) -> -20878.607 | G47: =B47+C47+D47+E47 -> -6307.386 | H47: =IFERROR(C47/F47,0%) -> -0.50652546
A48: [ CHI ] - CHIVACOA | B48: 4390.999 | C48: 28951.562 | D48: -53224.149 | E48: -7030.76 | F48: =SUM(D48,E48) -> -60254.909 | G48: =B48+C48+D48+E48 -> -26912.348 | H48: =IFERROR(C48/F48,0%) -> -0.4804847
A49: [ CHV ] - CHARALLAVE | B49: 11267.249 | C49: 82692.782 | D49: -138038.53 | E49: -19170.415 | F49: =SUM(D49,E49) -> -157208.94 | G49: =B49+C49+D49+E49 -> -63248.91 | H49: =IFERROR(C49/F49,0%) -> -0.52600559
A50: [ CJP ] - CINCO DE JULIO | B50: 5043.989 | C50: 27746.663 | D50: -49919.49 | E50: -6394.019 | F50: =SUM(D50,E50) -> -56313.509 | G50: =B50+C50+D50+E50 -> -23522.857 | H50: =IFERROR(C50/F50,0%) -> -0.49271771
A51: [ CLB ] - CALABOZO | B51: 7609.76 | C51: 47243.148 | D51: -87100.305 | E51: -12683.361 | F51: =SUM(D51,E51) -> -99783.666 | G51: =B51+C51+D51+E51 -> -44930.758 | H51: =IFERROR(C51/F51,0%) -> -0.47345573
A52: [ CLL ] - CALLAO | B52: 12015.378 | C52: 30474.522 | D52: -47645.74 | E52: -6837.114 | F52: =SUM(D52,E52) -> -54482.854 | G52: =B52+C52+D52+E52 -> -11992.954 | H52: =IFERROR(C52/F52,0%) -> -0.55934151
A53: [ CLP ] - CATIA LIFE PHONE | B53: 15583.996 | C53: 71880.752 | D53: -117329.44 | E53: -17034.954 | F53: =SUM(D53,E53) -> -134364.39 | G53: =B53+C53+D53+E53 -> -46899.647 | H53: =IFERROR(C53/F53,0%) -> -0.53496875
A54: [ CLT ] - COLONIA TOVAR | B54: 16727.687 | C54: 25911.399 | D54: -44452.949 | E54: -6328.682 | F54: =SUM(D54,E54) -> -50781.631 | G54: =B54+C54+D54+E54 -> -8142.545 | H54: =IFERROR(C54/F54,0%) -> -0.51025141
A55: [ CMC ] - CUA | B55: 8269.654 | C55: 48175.151 | D55: -90917.192 | E55: -11156.185 | F55: =SUM(D55,E55) -> -102073.38 | G55: =B55+C55+D55+E55 -> -45628.572 | H55: =IFERROR(C55/F55,0%) -> -0.47196588
A56: [ CMO ] - COMERCIO | B56: 12783.126 | C56: 35442.021 | D56: -60112.355 | E56: -9033.568 | F56: =SUM(D56,E56) -> -69145.923 | G56: =B56+C56+D56+E56 -> -20920.776 | H56: =IFERROR(C56/F56,0%) -> -0.51256849
...

Sheet RSM JULIO
A1: Centro de Costo | B1: Amortizacion | C1: % | D1: Arrendamiento | E1: % | F1: Fletes y Transporte | G1: % | H1: Gastos IT | I1: % | J1: Gastos de Personal | K1: % | L1: Gastos Financieros | M1: % | N1: Honorarios Profesionales | O1: % | P1: Impuestos, Tasas y Contribuciones | Q1: % | R1: Materiales, Mantenimiento y Reparaciones | S1: % | T1: Marketing y Promocion | U1: % | V1: Seguros | W1: % | X1: Servicios | Y1: % | Z1: Varios | AA1: % | AB1: Total Gastos | AC1: % | AD1: Total Costos | AE1: % | AF1: Ingresos | AG1: Otros Ingresos | AH1: Total Ingresos | AI1: Ingreso Bruto | AJ1: % impacto sobre ingresos generales | AK1: Gasto Aplicado por Venta | AL1: Monto Ingresos Bs | AM1: Factor de ingresos en bs | AN1: Gasto Aplicado Factor Ingreso Bs | AO1: Gasto aplicado | AP1: % | AQ1: Total General CC | AR1: Resultado - Gastos Distribuidos | AS1: % resultado en base a ingresos | BE1: NOTAS
A2: [ ABM ] - AV BOLIVAR DE MATURIN | B2: 0 | C2: 0 | D2: 0 | E2: 0 | F2: 0 | G2: 0 | H2: 0 | I2: 0 | J2: 0 | K2: 0 | M2: 0 | O2: 0 | Q2: 0 | R2: 391.179 | S2: 0 | U2: 0 | W2: 0 | Y2: 0 | AA2: 0 | AB2: 391.179 | AC2: 0 | AE2: 0 | AF2: 0 | AG2: 0 | AH2: =SUM(AF2,AG2) -> 0 | AI2: =((AF2+AG2)*-1) -> 0 | AJ2: =AI2/($AI$224) -> 0 | AK2: =AJ2*($G$260+$G$313-$B$406) -> 0 | AL2: 0 | AM2: =AL2/AL$224 -> 0 | AN2: =(AM2*$B$406) -> 0 | AO2: =AN2+AK2 -> 0 | AP2: 0 | AQ2: =AB2+AD2+AH2 -> 391.179 | AR2: =AQ2+AO2 -> 391.179 | AS2: 0 | AU2: RESULTADOS ANTES DE DISTRIBUCION JULIO 2026 | BA2: RESULTADOS DESPUES DE DISTRIBUCION JULIO 2026 | BE2: 1- Porcentaje impacto sobre ingresos generales: Analisis vertical de los ingresos por tienda contra el monto total de ingresos
A3: [ ACB ] - AV LIBERTADOR CIUDAD BOLIVAR | B3: 0 | C3: =$B3/$AI3 -> 0 | D3: 1200 | E3: =$D3/$AI3 -> 0.024433315 | F3: 0 | G3: =$F3/$AI3 -> 0 | H3: 0 | I3: =$H3/$AI3 -> 0 | J3: 3343.958 | K3: =$J3/$AI3 -> 0.068086649 | M3: =$L3/$AI3 -> 0 | O3: =$N3/$AI3 -> 0 | P3: 171.01 | Q3: =$P3/$AI3 -> 0.003481951 | R3: 4800.132 | S3: =$R3/$AI3 -> 0.097735948 | U3: =$T3/$AI3 -> 0 | W3: =$V3/$AI3 -> 0 | X3: 174.2 | Y3: =$X3/$AI3 -> 0.0035469029 | Z3: 176.579 | AA3: =$Z3/$AI3 -> 0.003595342 | AB3: 9865.879 | AC3: =$AB3/AI3 -> 0.20088011 | AD3: 22717.278 | AE3: =$AD3/$AI3 -> 0.46254868 | AF3: -42850.541 | AG3: -6262.729 | AH3: =SUM(AF3,AG3) -> -49113.27 | AI3: =((AF3+AG3)*-1) -> 49113.27 | AJ3: =AI3/($AI$224) -> 0.0037479444 | AK3: =AJ3*($G$260+$G$313-$B$406) -> 6620.085 | AL3: 15353.841 | AM3: =AL3/AL$224 -> 0.0032585803 | AN3: =(AM3*$B$406) -> 4430.3168 | AO3: =AN3+AK3 -> 11050.402 | AP3: =$AO3/$AI3 -> 0.22499829 | AQ3: =AB3+AD3+AH3 -> -16530.113 | AR3: =AQ3+AO3 -> -5479.7111 | AS3: =AR3/AI3 -> -0.11157292 | AU3: Perdida | AV3: 17 tiendas | AW3: 57718.74 | BA3: Perdida | BB3: 30 tiendas | BC3: 101304.26
A4: [ ACG ] - ACHAGUAS | B4: 0 | C4: =$B4/$AI4 -> 0 | D4: 940 | E4: =$D4/$AI4 -> 0.016508077 | F4: 0 | G4: =$F4/$AI4 -> 0 | H4: 0 | I4: =$H4/$AI4 -> 0 | J4: 2821.057 | K4: =$J4/$AI4 -> 0.049542795 | M4: =$L4/$AI4 -> 0 | O4: =$N4/$AI4 -> 0 | P4: 62.92 | Q4: =$P4/$AI4 -> 0.0011049875 | R4: 502.625 | S4: =$R4/$AI4 -> 0.0088269919 | U4: =$T4/$AI4 -> 0 | W4: =$V4/$AI4 -> 0 | X4: 287.09 | Y4: =$X4/$AI4 -> 0.0050418127 | Z4: 99.996 | AA4: =$Z4/$AI4 -> 0.0017561082 | AB4: 4713.688 | AC4: =$AB4/AI4 -> 0.082780772 | AD4: 29078.434 | AE4: =$AD4/$AI4 -> 0.51066919 | AF4: -49631.89 | AG4: -7309.932 | AH4: =SUM(AF4,AG4) -> -56941.822 | AI4: =((AF4+AG4)*-1) -> 56941.822 | AJ4: =AI4/($AI$224) -> 0.0043453588 | AK4: =AJ4*($G$260+$G$313-$B$406) -> 7675.3127 | AL4: 22324.722 | AM4: =AL4/AL$224 -> 0.0047380258 | AN4: =(AM4*$B$406) -> 6441.7488 | AO4: =AN4+AK4 -> 14117.061 | AP4: =$AO4/$AI4 -> 0.24792079 | AQ4: =AB4+AD4+AH4 -> -23149.7 | AR4: =AQ4+AO4 -> -9032.6385 | AS4: =AR4/AI4 -> -0.15862925 | AU4: Ganancias Hasta $10,000 | AV4: 35 tiendas | AW4: -141712.34 | BA4: Ganancias Hasta $10,000 | BB4: 103 tiendas | BC4: -515419.16 | BE4: 2- Gasto aplicado por venta: Se toman los ingresos costos y gastos mas los gastos del corporativo menos el diferencial de cambio
A5: [ ACO ] - ANACO | B5: 0 | C5: =$B5/$AI5 -> 0 | D5: 1700 | E5: =$D5/$AI5 -> 0.014298085 | F5: 0 | G5: =$F5/$AI5 -> 0 | H5: 0 | I5: =$H5/$AI5 -> 0 | J5: 5335.908 | K5: =$J5/$AI5 -> 0.044878391 | M5: =$L5/$AI5 -> 0 | O5: =$N5/$AI5 -> 0 | P5: 104.24 | Q5: =$P5/$AI5 -> 0.00087672492 | R5: 88.044 | S5: =$R5/$AI5 -> 0.00074050622 | U5: =$T5/$AI5 -> 0 | W5: =$V5/$AI5 -> 0 | X5: 123.32 | Y5: =$X5/$AI5 -> 0.0010371999 | Z5: 51.832 | AA5: =$Z5/$AI5 -> 0.00043594019 | AB5: 7403.344 | AC5: =$AB5/AI5 -> 0.062266847 | AD5: 60262.727 | AE5: =$AD5/$AI5 -> 0.50684799 | AF5: -104454 | AG5: -14443.039 | AH5: =SUM(AF5,AG5) -> -118897.04 | AI5: =((AF5+AG5)*-1) -> 118897.04 | AJ5: =AI5/($AI$224) -> 0.0090733015 | AK5: =AJ5*($G$260+$G$313-$B$406) -> 16026.392 | AL5: 42151.387 | AM5: =AL5/AL$224 -> 0.0089458836 | AN5: =(AM5*$B$406) -> 12162.689 | AO5: =AN5+AK5 -> 28189.081 | AP5: =$AO5/$AI5 -> 0.23708816 | AQ5: =AB5+AD5+AH5 -> -51230.972 | AR5: =AQ5+AO5 -> -23041.891 | AS5: =AR5/AI5 -> -0.193797 | AU5: Ganancia Mayor A $10,000 | AV5: 170 tiendas | AW5: -5025592 | BA5: Ganancia Mayor A $10,000 | BB5: 89 tiendas | BC5: -1569561.5
A6: [ ADO ] - ALTAGRACIA DEL ORITUCO | B6: 0 | C6: =$B6/$AI6 -> 0 | D6: 730 | E6: =$D6/$AI6 -> 0.0086751594 | F6: 0 | G6: =$F6/$AI6 -> 0 | H6: 0 | I6: =$H6/$AI6 -> 0 | J6: 4044.558 | K6: =$J6/$AI6 -> 0.048064637 | M6: =$L6/$AI6 -> 0 | O6: =$N6/$AI6 -> 0 | P6: 70.29 | Q6: =$P6/$AI6 -> 0.00083531089 | R6: 292.649 | S6: =$R6/$AI6 -> 0.0034777763 | T6: 1.89 | U6: =$T6/$AI6 -> 2.2460344e-05 | W6: =$V6/$AI6 -> 0 | X6: 281.86 | Y6: =$X6/$AI6 -> 0.0033495622 | Z6: -6.595 | AA6: =$Z6/$AI6 -> -7.8373529e-05 | AB6: 5414.652 | AC6: =$AB6/AI6 -> 0.064346533 | AD6: 41163.746 | AE6: =$AD6/$AI6 -> 0.4891809 | AF6: -73293.141 | AG6: -10855.169 | AH6: =SUM(AF6,AG6) -> -84148.31 | AI6: =((AF6+AG6)*-1) -> 84148.31 | AJ6: =AI6/($AI$224) -> 0.0064215473 | AK6: =AJ6*($G$260+$G$313-$B$406) -> 11342.535 | AL6: 32162.211 | AM6: =AL6/AL$224 -> 0.0068258583 | AN6: =(AM6*$B$406) -> 9280.3345 | AO6: =AN6+AK6 -> 20622.869 | AP6: =$AO6/$AI6 -> 0.24507764 | AQ6: =AB6+AD6+AH6 -> -37569.912 | AR6: =AQ6+AO6 -> -16947.043 | AS6: =AR6/AI6 -> -0.20139493 | AU6: TOTALES | AV6: 222 | AW6: =SUM(AW3:AW5) -> -5109585.6 | BA6: TOTALES | BB6: 222 | BC6: =SUM(BC3:BC5) -> -1983676.4 | BE6: 3- Monto ingresos en bs: Son todos los metodos de pago recibidos en VES (pago movil, biopago, efectivo bs , punto de venta, etc) este dado es suministrado por la Gerencia de Cuentas por Pagar
A7: [ ADS - BQT ] - AEDOS BARQUISIMETO | B7: 0 | C7: 0 | D7: 0 | E7: 0 | F7: 0 | G7: 0 | H7: 0 | I7: 0 | J7: 0 | K7: 0 | M7: 0 | O7: 0 | Q7: 0 | S7: 0 | U7: 0 | W7: 0 | Y7: 0 | Z7: -11.033 | AA7: 0 | AB7: -11.033 | AC7: 0 | AE7: 0 | AF7: 0 | AG7: 0 | AH7: =SUM(AF7,AG7) -> 0 | AI7: =((AF7+AG7)*-1) -> 0 | AJ7: =AI7/($AI$224) -> 0 | AK7: =AJ7*($G$260+$G$313-$B$406) -> 0 | AL7: 0 | AM7: =AL7/AL$224 -> 0 | AN7: =(AM7*$B$406) -> 0 | AO7: =AN7+AK7 -> 0 | AP7: 0 | AQ7: =AB7+AD7+AH7 -> -11.033 | AR7: =AQ7+AO7 -> -11.033 | AS7: 0
A8: [ ADS - TCY ] - AEDOS TOCUYITO | B8: 0 | C8: =$B8/$AI8 -> 0 | D8: 0 | E8: =$D8/$AI8 -> 0 | F8: 30 | G8: =$F8/$AI8 -> 0.0015520647 | H8: 0 | I8: =$H8/$AI8 -> 0 | J8: 924 | K8: =$J8/$AI8 -> 0.047803593 | M8: =$L8/$AI8 -> 0 | O8: =$N8/$AI8 -> 0 | P8: 433.46 | Q8: =$P8/$AI8 -> 0.022425266 | R8: 10854.95 | S8: =$R8/$AI8 -> 0.56158616 | T8: 90 | U8: =$T8/$AI8 -> 0.0046561941 | W8: =$V8/$AI8 -> 0 | X8: 89.1 | Y8: =$X8/$AI8 -> 0.0046096322 | Z8: 12700.181 | AA8: =$Z8/$AI8 -> 0.65705009 | AB8: 25121.691 | AC8: =$AB8/AI8 -> 1.299683 | AD8: 6022.502 | AE8: =$AD8/$AI8 -> 0.31157709 | AF8: -17002.863 | AG8: -2326.228 | AH8: =SUM(AF8,AG8) -> -19329.091 | AI8: =((AF8+AG8)*-1) -> 19329.091 | AJ8: =AI8/($AI$224) -> 0.0014750465 | AK8: =AJ8*($G$260+$G$313-$B$406) -> 2605.4104 | AL8: 14498.62 | AM8: =AL8/AL$224 -> 0.0030770746 | AN8: =(AM8*$B$406) -> 4183.5445 | AO8: =AN8+AK8 -> 6788.9549 | AP8: =$AO8/$AI8 -> 0.35122991 | AQ8: =AB8+AD8+AH8 -> 11815.102 | AR8: =AQ8+AO8 -> 18604.057 | AS8: =AR8/AI8 -> 0.96249001 | AU8: ARRENDAMIENTO | BE8: 4- Factor de Ingresos en bs: El impacto que tiene cada tienda sobre el total del ingreso en bolivares del Período
A9: [ ANT ] - ANTIMANO | B9: 0 | C9: =$B9/$AI9 -> 0 | D9: 1500 | E9: =$D9/$AI9 -> 0.13042388 | F9: 0 | G9: =$F9/$AI9 -> 0 | H9: 0 | I9: =$H9/$AI9 -> 0 | J9: 3892.129 | K9: =$J9/$AI9 -> 0.33841772 | M9: =$L9/$AI9 -> 0 | N9: 228.45 | O9: =$N9/$AI9 -> 0.019863557 | P9: 98.63 | Q9: =$P9/$AI9 -> 0.0085758051 | R9: 877.585 | S9: =$R9/$AI9 -> 0.076305363 | U9: =$T9/$AI9 -> 0 | W9: =$V9/$AI9 -> 0 | X9: 112.89 | Y9: =$X9/$AI9 -> 0.0098157015 | Z9: 13.17 | AA9: =$Z9/$AI9 -> 0.0011451217 | AB9: 6722.854 | AC9: =$AB9/AI9 -> 0.58454715 | AD9: 5543.328 | AE9: =$AD9/$AI9 -> 0.48198824 | AF9: -10027.621 | AG9: -1473.34 | AH9: =SUM(AF9,AG9) -> -11500.961 | AI9: =((AF9+AG9)*-1) -> 11500.961 | AJ9: =AI9/($AI$224) -> 0.00087766427 | AK9: =AJ9*($G$260+$G$313-$B$406) -> 1550.2397 | AL9: 4371.0637 | AM9: =AL9/AL$224 -> 0.00092768068 | AN9: =(AM9*$B$406) -> 1261.2607 | AO9: =AN9+AK9 -> 2811.5004 | AP9: =$AO9/$AI9 -> 0.24445787 | AQ9: =AB9+AD9+AH9 -> 765.221 | AR9: =AQ9+AO9 -> 3576.7214 | AS9: =AR9/AI9 -> 0.31099326 | AU9: Gastos superiores a $2000 | AV9: 30 tiendas | AW9: 87044.62
A10: [ APU ] - APURE | B10: 0 | C10: =$B10/$AI10 -> 0 | D10: 1420 | E10: =$D10/$AI10 -> 0.015176192 | F10: 0 | G10: =$F10/$AI10 -> 0 | H10: 47.2 | I10: =$H10/$AI10 -> 0.00050444806 | J10: 4245.454 | K10: =$J10/$AI10 -> 0.045373115 | M10: =$L10/$AI10 -> 0 | O10: =$N10/$AI10 -> 0 | P10: 119.18 | Q10: =$P10/$AI10 -> 0.0012737314 | R10: 732.844 | S10: =$R10/$AI10 -> 0.0078322402 | U10: =$T10/$AI10 -> 0 | W10: =$V10/$AI10 -> 0 | X10: 229.98 | Y10: =$X10/$AI10 -> 0.0024579018 | Z10: 461.543 | AA10: =$Z10/$AI10 -> 0.0049327219 | AB10: 7256.201 | AC10: =$AB10/AI10 -> 0.07755035 | AD10: 49343.272 | AE10: =$AD10/$AI10 -> 0.52735419 | AF10: -81546.616 | AG10: -12020.995 | AH10: =SUM(AF10,AG10) -> -93567.611 | AI10: =((AF10+AG10)*-1) -> 93567.611 | AJ10: =AI10/($AI$224) -> 0.0071403554 | AK10: =AJ10*($G$260+$G$313-$B$406) -> 12612.183 | AL10: 35382.82 | AM10: =AL10/AL$224 -> 0.0075093754 | AN10: =(AM10*$B$406) -> 10209.634 | AO10: =AN10+AK10 -> 22821.817 | AP10: =$AO10/$AI10 -> 0.24390723 | AQ10: =AB10+AD10+AH10 -> -36968.138 | AR10: =AQ10+AO10 -> -14146.321 | AS10: =AR10/AI10 -> -0.15118822 | AU10: Gastos entre $1001 hasta $2000 | AV10: 69 tiendas | AW10: 102791.81 | BE10: 5- Gasto aplicado a diferencial de cambio: El gasto del diferencial de cambio (perdida por diferencia en cambio) que se aplica sobre el factor de ingresos en bolivares de cada tienda
A11: [ ARO - INT ] - AEROPUERTO INTERNACIONAL | B11: 0 | C11: 0 | D11: 215 | E11: 0 | F11: 0 | G11: 0 | H11: 0 | I11: 0 | J11: 1488.504 | K11: 0 | M11: 0 | O11: 0 | Q11: 0 | S11: 0 | U11: 0 | W11: 0 | X11: 100.23 | Y11: 0 | Z11: 3.35 | AA11: 0 | AB11: 1807.084 | AC11: 0 | AD11: -181.214 | AE11: 0 | AF11: 0 | AG11: 0 | AH11: =SUM(AF11,AG11) -> 0 | AI11: =((AF11+AG11)*-1) -> 0 | AJ11: =AI11/($AI$224) -> 0 | AK11: =AJ11*($G$260+$G$313-$B$406) -> 0 | AL11: 0 | AM11: =AL11/AL$224 -> 0 | AN11: =(AM11*$B$406) -> 0 | AO11: =AN11+AK11 -> 0 | AP11: 0 | AQ11: =AB11+AD11+AH11 -> 1625.87 | AR11: =AQ11+AO11 -> 1625.87 | AS11: 0 | AU11: Gastos entre $0 hasta $1000 | AV11: 123 tiendas | AW11: 52989.12
A12: [ ARO - NAC ] - AEROPUERTO NACIONAL | B12: 0 | C12: 0 | D12: 215 | E12: 0 | F12: 0 | G12: 0 | H12: 0 | I12: 0 | J12: 1477.455 | K12: 0 | M12: 0 | O12: 0 | Q12: 0 | R12: 258.207 | S12: 0 | U12: 0 | W12: 0 | X12: 85.23 | Y12: 0 | Z12: 138.372 | AA12: 0 | AB12: 2174.264 | AC12: 0 | AD12: 7697.841 | AE12: 0 | AF12: 0 | AG12: 0 | AH12: =SUM(AF12,AG12) -> 0 | AI12: =((AF12+AG12)*-1) -> 0 | AJ12: =AI12/($AI$224) -> 0 | AK12: =AJ12*($G$260+$G$313-$B$406) -> 0 | AL12: 0 | AM12: =AL12/AL$224 -> 0 | AN12: =(AM12*$B$406) -> 0 | AO12: =AN12+AK12 -> 0 | AP12: 0 | AQ12: =AB12+AD12+AH12 -> 9872.105 | AR12: =AQ12+AO12 -> 9872.105 | AS12: 0 | AU12: TOTALES | AV12: 222 | AW12: =SUM(AW9:AW11) -> 242825.55 | BE12: 6- Gasto Aplicado : Es el gasto aplicado por venta + el gasto aplicado a diferencia de cambio
A13: [ ARY ] - AROA YARACUY | B13: 0 | C13: 0 | D13: 0 | E13: 0 | F13: 0 | G13: 0 | H13: 0 | I13: 0 | J13: 0 | K13: 0 | M13: 0 | O13: 0 | Q13: 0 | R13: 9.74 | S13: 0 | U13: 0 | W13: 0 | Y13: 0 | Z13: 6.88 | AA13: 0 | AB13: 16.62 | AC13: 0 | AD13: -32.068 | AE13: 0 | AF13: 0 | AG13: 0 | AH13: =SUM(AF13,AG13) -> 0 | AI13: =((AF13+AG13)*-1) -> 0 | AJ13: =AI13/($AI$224) -> 0 | AK13: =AJ13*($G$260+$G$313-$B$406) -> 0 | AL13: 0 | AM13: =AL13/AL$224 -> 0 | AN13: =(AM13*$B$406) -> 0 | AO13: =AN13+AK13 -> 0 | AP13: 0 | AQ13: =AB13+AD13+AH13 -> -15.448 | AR13: =AQ13+AO13 -> -15.448 | AS13: 0
A14: [ ATV ] - ALTA VISTA | B14: -3100 | C14: =$B14/$AI14 -> -0.077263184 | D14: 1100 | E14: =$D14/$AI14 -> 0.027415969 | F14: 0 | G14: =$F14/$AI14 -> 0 | H14: 0 | I14: =$H14/$AI14 -> 0 | J14: 2174.073 | K14: =$J14/$AI14 -> 0.054185743 | M14: =$L14/$AI14 -> 0 | O14: =$N14/$AI14 -> 0 | Q14: =$P14/$AI14 -> 0 | R14: 54.171 | S14: =$R14/$AI14 -> 0.0013501368 | U14: =$T14/$AI14 -> 0 | W14: =$V14/$AI14 -> 0 | X14: 40.7 | Y14: =$X14/$AI14 -> 0.0010143908 | Z14: 41.244 | AA14: =$Z14/$AI14 -> 0.0010279493 | AB14: 310.188 | AC14: =$AB14/AI14 -> 0.0077310041 | AD14: 18339.91 | AE14: =$AD14/$AI14 -> 0.45709673 | AF14: -35063.775 | AG14: -5058.827 | AH14: =SUM(AF14,AG14) -> -40122.602 | AI14: =((AF14+AG14)*-1) -> 40122.602 | AJ14: =AI14/($AI$224) -> 0.0030618462 | AK14: =AJ14*($G$260+$G$313-$B$406) -> 5408.2132 | AL14: 13621.013 | AM14: =AL14/AL$224 -> 0.0028908181 | AN14: =(AM14*$B$406) -> 3930.3129 | AO14: =AN14+AK14 -> 9338.5261 | AP14: =$AO14/$AI14 -> 0.23274976 | AQ14: =AB14+AD14+AH14 -> -21472.504 | AR14: =AQ14+AO14 -> -12133.978 | AS14: =AR14/AI14 -> -0.30242251 | AU14: GASTOS DE PERSONAL | BE14: 7- Resultado de la tienda ( total general + gasto aplicado)
A15: [ AVM ] - AVENIDA MARIÑO | B15: 0 | C15: =$B15/$AI15 -> 0 | D15: 800 | E15: =$D15/$AI15 -> 0.018073194 | F15: 20 | G15: =$F15/$AI15 -> 0.00045182985 | H15: 0 | I15: =$H15/$AI15 -> 0 | J15: 2448.821 | K15: =$J15/$AI15 -> 0.055322522 | M15: =$L15/$AI15 -> 0 | N15: 10.06 | O15: =$N15/$AI15 -> 0.00022727042 | P15: 111.93 | Q15: =$P15/$AI15 -> 0.0025286658 | R15: 444.205 | S15: =$R15/$AI15 -> 0.010035254 | U15: =$T15/$AI15 -> 0 | W15: =$V15/$AI15 -> 0 | X15: 185.98 | Y15: =$X15/$AI15 -> 0.0042015658 | Z15: 44.692 | AA15: =$Z15/$AI15 -> 0.001009659 | AB15: 4065.688 | AC15: =$AB15/AI15 -> 0.091849961 | AD15: 24877.791 | AE15: =$AD15/$AI15 -> 0.56202643 | AF15: -44264.45 | AG15: 0 | AH15: =SUM(AF15,AG15) -> -44264.45 | AI15: =((AF15+AG15)*-1) -> 44264.45 | AJ15: =AI15/($AI$224) -> 0.00337792 | AK15: =AJ15*($G$260+$G$313-$B$406) -> 5966.502 | AL15: 14473.401 | AM15: =AL15/AL$224 -> 0.0030717225 | AN15: =(AM15*$B$406) -> 4176.2678 | AO15: =AN15+AK15 -> 10142.77 | AP15: =$AO15/$AI15 -> 0.22914031 | AQ15: =AB15+AD15+AH15 -> -15320.971 | AR15: =AQ15+AO15 -> -5178.2012 | AS15: =AR15/AI15 -> -0.1169833 | AU15: Gastos superiores a $6000 | AV15: 25 tiendas | AW15: 199615.04
A16: [ BAC ] - BUENOS AIRES CANGURO | B16: 0 | C16: =$B16/$AI16 -> 0 | D16: 1100 | E16: =$D16/$AI16 -> 0.024345378 | F16: 22.5 | G16: =$F16/$AI16 -> 0.00049797365 | H16: 47.2 | I16: =$H16/$AI16 -> 0.001044638 | J16: 3563.221 | K16: =$J16/$AI16 -> 0.078861785 | M16: =$L16/$AI16 -> 0 | O16: =$N16/$AI16 -> 0 | P16: 165.95 | Q16: =$P16/$AI16 -> 0.0036728323 | R16: 117.381 | S16: =$R16/$AI16 -> 0.0025978953 | U16: =$T16/$AI16 -> 0 | W16: =$V16/$AI16 -> 0 | X16: 310.72 | Y16: =$X16/$AI16 -> 0.0068769054 | Z16: 32.403 | AA16: =$Z16/$AI16 -> 0.00071714845 | AB16: 5359.375 | AC16: =$AB16/AI16 -> 0.11861456 | AD16: 22589.678 | AE16: =$AD16/$AI16 -> 0.49995841 | AF16: -39774.96 | AG16: -5408.154 | AH16: =SUM(AF16,AG16) -> -45183.114 | AI16: =((AF16+AG16)*-1) -> 45183.114 | AJ16: =AI16/($AI$224) -> 0.0034480253 | AK16: =AJ16*($G$260+$G$313-$B$406) -> 6090.3307 | AL16: 15150.12 | AM16: =AL16/AL$224 -> 0.0032153439 | AN16: =(AM16*$B$406) -> 4371.5333 | AO16: =AN16+AK16 -> 10461.864 | AP16: =$AO16/$AI16 -> 0.23154367 | AQ16: =AB16+AD16+AH16 -> -17234.061 | AR16: =AQ16+AO16 -> -6772.1969 | AS16: =AR16/AI16 -> -0.14988336 | AU16: Gastos entre $3001 hasta $6000 | AV16: 114 tiendas | AW16: 468218.01 | BE16: OBSERVACION
A17: [ BCC ] - BISCUCUY | B17: 0 | C17: =$B17/$AI17 -> 0 | D17: 600 | E17: =$D17/$AI17 -> 0.018180168 | F17: 0 | G17: =$F17/$AI17 -> 0 | H17: 0 | I17: =$H17/$AI17 -> 0 | J17: 2727.408 | K17: =$J17/$AI17 -> 0.082641227 | M17: =$L17/$AI17 -> 0 | O17: =$N17/$AI17 -> 0 | Q17: =$P17/$AI17 -> 0 | R17: 4273.529 | S17: =$R17/$AI17 -> 0.12948913 | U17: =$T17/$AI17 -> 0 | W17: =$V17/$AI17 -> 0 | X17: 29.47 | Y17: =$X17/$AI17 -> 0.00089294926 | Z17: 634.186 | AA17: =$Z17/$AI17 -> 0.019216014 | AB17: 8264.593 | AC17: =$AB17/AI17 -> 0.25041948 | AD17: 17173.338 | AE17: =$AD17/$AI17 -> 0.52035696 | AF17: -28714.826 | AG17: -4288.169 | AH17: =SUM(AF17,AG17) -> -33002.995 | AI17: =((AF17+AG17)*-1) -> 33002.995 | AJ17: =AI17/($AI$224) -> 0.002518533 | AK17: =AJ17*($G$260+$G$313-$B$406) -> 4448.5458 | AL17: 12384.42 | AM17: =AL17/AL$224 -> 0.0026283732 | AN17: =(AM17*$B$406) -> 3573.4968 | AO17: =AN17+AK17 -> 8022.0427 | AP17: =$AO17/$AI17 -> 0.24307014 | AQ17: =AB17+AD17+AH17 -> -7565.064 | AR17: =AQ17+AO17 -> 456.97867 | AS17: =AR17/AI17 -> 0.013846582 | AU17: Gastos entre $0 hasta $3000 | AV17: 83 tiendas | AW17: 135782.46 | BE17: Los ingresos, costos y gastos del cendis se distribuyen al igual que los gastos del corporativo entre las tiendas en funcion de la venta.
A18: [ BCD ] - BARINAS CC DORADO | B18: 0 | C18: =$B18/$AI18 -> 0 | D18: 350 | E18: =$D18/$AI18 -> 0.010770657 | F18: 0 | G18: =$F18/$AI18 -> 0 | H18: 0 | I18: =$H18/$AI18 -> 0 | J18: 2436.293 | K18: =$J18/$AI18 -> 0.074972788 | M18: =$L18/$AI18 -> 0 | O18: =$N18/$AI18 -> 0 | P18: 57.82 | Q18: =$P18/$AI18 -> 0.0017793125 | R18: 240.771 | S18: =$R18/$AI18 -> 0.0074093195 | U18: =$T18/$AI18 -> 0 | W18: =$V18/$AI18 -> 0 | X18: 345.33 | Y18: =$X18/$AI18 -> 0.010626945 | Z18: 131.115 | AA18: =$Z18/$AI18 -> 0.0040348419 | AB18: 3561.329 | AC18: =$AB18/AI18 -> 0.10959386 | AD18: 16467.36 | AE18: =$AD18/$AI18 -> 0.50675509 | AF18: -28423.281 | AG18: -4072.416 | AH18: =SUM(AF18,AG18) -> -32495.697 | AI18: =((AF18+AG18)*-1) -> 32495.697 | AJ18: =AI18/($AI$224) -> 0.0024798199 | AK18: =AJ18*($G$260+$G$313-$B$406) -> 4380.166 | AL18: 11290.267 | AM18: =AL18/AL$224 -> 0.0023961588 | AN18: =(AM18*$B$406) -> 3257.7815 | AO18: =AN18+AK18 -> 7637.9476 | AP18: =$AO18/$AI18 -> 0.23504489 | AQ18: =AB18+AD18+AH18 -> -12467.008 | AR18: =AQ18+AO18 -> -4829.0604 | AS18: =AR18/AI18 -> -0.14860615 | AU18: TOTALES | AV18: 222 | AW18: =SUM(AW15:AW17) -> 803615.51
A19: [ BCN ] - BARCELONA | B19: 0 | C19: =$B19/$AI19 -> 0 | D19: 2508.33 | E19: =$D19/$AI19 -> 0.03159095 | F19: 0 | G19: =$F19/$AI19 -> 0 | H19: 0 | I19: =$H19/$AI19 -> 0 | J19: 4308.157 | K19: =$J19/$AI19 -> 0.054258718 | M19: =$L19/$AI19 -> 0 | O19: =$N19/$AI19 -> 0 | P19: 357.02 | Q19: =$P19/$AI19 -> 0.0044964581 | R19: 11.99 | S19: =$R19/$AI19 -> 0.00015100704 | U19: =$T19/$AI19 -> 0 | W19: =$V19/$AI19 -> 0 | X19: 109.29 | Y19: =$X19/$AI19 -> 0.0013764436 | Z19: 35.715 | AA19: =$Z19/$AI19 -> 0.00044980954 | AB19: 7330.502 | AC19: =$AB19/AI19 -> 0.092323386 | AD19: 38567.289 | AE19: =$AD19/$AI19 -> 0.48573245 | AF19: -69454.678 | AG19: -9945.594 | AH19: =SUM(AF19,AG19) -> -79400.272 | AI19: =((AF19+AG19)*-1) -> 79400.272 | AJ19: =AI19/($AI$224) -> 0.0060592138 | AK19: =AJ19*($G$260+$G$313-$B$406) -> 10702.536 | AL19: 29744.153 | AM19: =AL19/AL$224 -> 0.0063126685 | AN19: =(AM19*$B$406) -> 8582.6093 | AO19: =AN19+AK19 -> 19285.146 | AP19: =$AO19/$AI19 -> 0.24288513 | AQ19: =AB19+AD19+AH19 -> -33502.481 | AR19: =AQ19+AO19 -> -14217.335 | AS19: =AR19/AI19 -> -0.17905903
A20: [ BCO ] - BOCONO | B20: 0 | C20: =$B20/$AI20 -> 0 | D20: 1030 | E20: =$D20/$AI20 -> 0.021256953 | F20: 66.98 | G20: =$F20/$AI20 -> 0.0013823211 | H20: 0 | I20: =$H20/$AI20 -> 0 | J20: 3584.88 | K20: =$J20/$AI20 -> 0.073984104 | M20: =$L20/$AI20 -> 0 | O20: =$N20/$AI20 -> 0 | P20: 183.06 | Q20: =$P20/$AI20 -> 0.0037779591 | R20: 932.268 | S20: =$R20/$AI20 -> 0.019239978 | U20: =$T20/$AI20 -> 0 | W20: =$V20/$AI20 -> 0 | X20: 273.55 | Y20: =$X20/$AI20 -> 0.0056454753 | Z20: 32.211 | AA20: =$Z20/$AI20 -> 0.00066476478 | AB20: 6102.949 | AC20: =$AB20/AI20 -> 0.12595156 | AD20: 23941.996 | AE20: =$AD20/$AI20 -> 0.49411058 | AF20: -42456.901 | AG20: -5997.832 | AH20: =SUM(AF20,AG20) -> -48454.733 | AI20: =((AF20+AG20)*-1) -> 48454.733 | AJ20: =AI20/($AI$224) -> 0.0036976899 | AK20: =AJ20*($G$260+$G$313-$B$406) -> 6531.3194 | AL20: 22349.9 | AM20: =AL20/AL$224 -> 0.0047433694 | AN20: =(AM20*$B$406) -> 6449.0139 | AO20: =AN20+AK20 -> 12980.333 | AP20: =$AO20/$AI20 -> 0.26788577 | AQ20: =AB20+AD20+AH20 -> -18409.788 | AR20: =AQ20+AO20 -> -5429.4547 | AS20: =AR20/AI20 -> -0.1120521 | AU20: TOTAL DE GASTOS
A21: [ BJM ] - BEJUMA | B21: 0 | C21: =$B21/$AI21 -> 0 | D21: 700 | E21: =$D21/$AI21 -> 0.01439139 | F21: 239.18 | G21: =$F21/$AI21 -> 0.0049173324 | H21: 0 | I21: =$H21/$AI21 -> 0 | J21: 3011.965 | K21: =$J21/$AI21 -> 0.061923376 | M21: =$L21/$AI21 -> 0 | O21: =$N21/$AI21 -> 0 | P21: 59.23 | Q21: =$P21/$AI21 -> 0.0012177172 | R21: 2486.392 | S21: =$R21/$AI21 -> 0.051118053 | U21: =$T21/$AI21 -> 0 | W21: =$V21/$AI21 -> 0 | X21: 157.32 | Y21: =$X21/$AI21 -> 0.0032343621 | Z21: -43.906 | AA21: =$Z21/$AI21 -> -0.0009026691 | AB21: 6610.181 | AC21: =$AB21/AI21 -> 0.13589956 | AD21: 24201.919 | AE21: =$AD21/$AI21 -> 0.49757036 | AF21: -42637.384 | AG21: -6002.81 | AH21: =SUM(AF21,AG21) -> -48640.194 | AI21: =((AF21+AG21)*-1) -> 48640.194 | AJ21: =AI21/($AI$224) -> 0.0037118429 | AK21: =AJ21*($G$260+$G$313-$B$406) -> 6556.3181 | AL21: 17717.493 | AM21: =AL21/AL$224 -> 0.0037602233 | AN21: =(AM21*$B$406) -> 5112.3432 | AO21: =AN21+AK21 -> 11668.661 | AP21: =$AO21/$AI21 -> 0.23989751 | AQ21: =AB21+AD21+AH21 -> -17828.094 | AR21: =AQ21+AO21 -> -6159.4327 | AS21: =AR21/AI21 -> -0.12663257 | AU21: Gastos superiores a $7000 | AV21: 82 tiendas | AW21: 876718.67
A22: [ BLS ] - BAILADORES | B22: 0 | C22: =$B22/$AI22 -> 0 | D22: 400 | E22: =$D22/$AI22 -> 0.14770612 | F22: 0 | G22: =$F22/$AI22 -> 0 | H22: 0 | I22: =$H22/$AI22 -> 0 | J22: 0 | K22: =$J22/$AI22 -> 0 | M22: =$L22/$AI22 -> 0 | N22: 240 | O22: =$N22/$AI22 -> 0.088623674 | P22: 87.56 | Q22: =$P22/$AI22 -> 0.032332871 | R22: 2.315 | S22: =$R22/$AI22 -> 0.00085484919 | U22: =$T22/$AI22 -> 0 | W22: =$V22/$AI22 -> 0 | X22: 53.98 | Y22: =$X22/$AI22 -> 0.019932941 | Z22: 0.151 | AA22: =$Z22/$AI22 -> 5.5759062e-05 | AB22: 784.006 | AC22: =$AB22/AI22 -> 0.28950622 | AD22: 815.361 | AE22: =$AD22/$AI22 -> 0.30108453 | AF22: -2366.67 | AG22: -341.41 | AH22: =SUM(AF22,AG22) -> -2708.08 | AI22: =((AF22+AG22)*-1) -> 2708.08 | AJ22: =AI22/($AI$224) -> 0.00020665969 | AK22: =AJ22*($G$260+$G$313-$B$406) -> 365.02802 | AL22: 1079.4016 | AM22: =AL22/AL$224 -> 0.00022908383 | AN22: =(AM22*$B$406) -> 311.45894 | AO22: =AN22+AK22 -> 676.48697 | AP22: =$AO22/$AI22 -> 0.24980317 | AQ22: =AB22+AD22+AH22 -> -1108.713 | AR22: =AQ22+AO22 -> -432.22603 | AS22: =AR22/AI22 -> -0.15960608 | AU22: Gastos entre $4001 hasta $7000 | AV22: 88 tiendas | AW22: 453550.48
A23: [ BNS ] - BARINAS SHOP | B23: 0 | C23: =$B23/$AI23 -> 0 | D23: 2400 | E23: =$D23/$AI23 -> 0.020077593 | F23: 49.76 | G23: =$F23/$AI23 -> 0.00041627542 | H23: 0 | I23: =$H23/$AI23 -> 0 | J23: 6859.219 | K23: =$J23/$AI23 -> 0.057381918 | M23: =$L23/$AI23 -> 0 | O23: =$N23/$AI23 -> 0 | P23: 200.74 | Q23: =$P23/$AI23 -> 0.0016793233 | R23: 804.023 | S23: =$R23/$AI23 -> 0.0067261859 | U23: =$T23/$AI23 -> 0 | W23: =$V23/$AI23 -> 0 | X23: 231.44 | Y23: =$X23/$AI23 -> 0.0019361492 | Z23: 651.377 | AA23: =$Z23/$AI23 -> 0.0054492008 | AB23: 11196.559 | AC23: =$AB23/AI23 -> 0.093666646 | AD23: 63765.986 | AE23: =$AD23/$AI23 -> 0.53344479 | AF23: -104268.82 | AG23: -15267.428 | AH23: =SUM(AF23,AG23) -> -119536.24 | AI23: =((AF23+AG23)*-1) -> 119536.24 | AJ23: =AI23/($AI$224) -> 0.0091220803 | AK23: =AJ23*($G$260+$G$313-$B$406) -> 16112.552 | AL23: 41233.126 | AM23: =AL23/AL$224 -> 0.0087509989 | AN23: =(AM23*$B$406) -> 11897.727 | AO23: =AN23+AK23 -> 28010.278 | AP23: =$AO23/$AI23 -> 0.23432457 | AQ23: =AB23+AD23+AH23 -> -44573.699 | AR23: =AQ23+AO23 -> -16563.421 | AS23: =AR23/AI23 -> -0.138564 | AU23: Gastos entre $0 hasta $4000 | AV23: 52 tiendas | AW23: 83993.31
A24: [ BRC ] - BARRANCAS | B24: 0 | C24: =$B24/$AI24 -> 0 | D24: 600 | E24: =$D24/$AI24 -> 0.015589314 | F24: 26.87 | G24: =$F24/$AI24 -> 0.00069814146 | H24: 0 | I24: =$H24/$AI24 -> 0 | J24: 2970.428 | K24: =$J24/$AI24 -> 0.077178226 | M24: =$L24/$AI24 -> 0 | O24: =$N24/$AI24 -> 0 | P24: 146.84 | Q24: =$P24/$AI24 -> 0.0038152248 | R24: 85.385 | S24: =$R24/$AI24 -> 0.0022184893 | U24: =$T24/$AI24 -> 0 | W24: =$V24/$AI24 -> 0 | X24: 172.28 | Y24: =$X24/$AI24 -> 0.0044762118 | Z24: 26.777 | AA24: =$Z24/$AI24 -> 0.00069572511 | AB24: 4028.58 | AC24: =$AB24/AI24 -> 0.10467133 | AD24: 19262.203 | AE24: =$AD24/$AI24 -> 0.50047423 | AF24: -33678.031 | AG24: -4809.871 | AH24: =SUM(AF24,AG24) -> -38487.902 | AI24: =((AF24+AG24)*-1) -> 38487.902 | AJ24: =AI24/($AI$224) -> 0.0029370986 | AK24: =AJ24*($G$260+$G$313-$B$406) -> 5187.8685 | AL24: 17686.951 | AM24: =AL24/AL$224 -> 0.0037537413 | AN24: =(AM24*$B$406) -> 5103.5303 | AO24: =AN24+AK24 -> 10291.399 | AP24: =$AO24/$AI24 -> 0.26739308 | AQ24: =AB24+AD24+AH24 -> -15197.119 | AR24: =AQ24+AO24 -> -4905.7202 | AS24: =AR24/AI24 -> -0.12746136 | AU24: TOTALES | AV24: 222 | AW24: =SUM(AW21:AW23) -> 1414262.5
A25: [ BTA ] - BARUTA | B25: 0 | C25: =$B25/$AI25 -> 0 | D25: 1800 | E25: =$D25/$AI25 -> 0.02607226 | F25: 0 | G25: =$F25/$AI25 -> 0 | H25: 0 | I25: =$H25/$AI25 -> 0 | J25: 4635.075 | K25: =$J25/$AI25 -> 0.067137157 | M25: =$L25/$AI25 -> 0 | O25: =$N25/$AI25 -> 0 | P25: 115.02 | Q25: =$P25/$AI25 -> 0.0016660174 | R25: 4133.532 | S25: =$R25/$AI25 -> 0.059872513 | U25: =$T25/$AI25 -> 0 | V25: 425 | W25: =$V25/$AI25 -> 0.0061559504 | X25: 380.17 | Y25: =$X25/$AI25 -> 0.0055066063 | Z25: 42.266 | AA25: =$Z25/$AI25 -> 0.00061220564 | AB25: 11531.063 | AC25: =$AB25/AI25 -> 0.16702271 | AD25: 32236.414 | AE25: =$AD25/$AI25 -> 0.46693121 | AF25: -60104.394 | AG25: -8934.499 | AH25: =SUM(AF25,AG25) -> -69038.893 | AI25: =((AF25+AG25)*-1) -> 69038.893 | AJ25: =AI25/($AI$224) -> 0.0052685136 | AK25: =AJ25*($G$260+$G$313-$B$406) -> 9305.9033 | AL25: 28880.64 | AM25: =AL25/AL$224 -> 0.0061294032 | AN25: =(AM25*$B$406) -> 8333.4446 | AO25: =AN25+AK25 -> 17639.348 | AP25: =$AO25/$AI25 -> 0.25549871 | AQ25: =AB25+AD25+AH25 -> -25271.416 | AR25: =AQ25+AO25 -> -7632.0681 | AS25: =AR25/AI25 -> -0.11054737
A26: [ BVC ] - BAZAR VALENCIA CANGURO | B26: 0 | C26: =$B26/$AI26 -> 0 | D26: 3650 | E26: =$D26/$AI26 -> 0.029540196 | F26: 128.54 | G26: =$F26/$AI26 -> 0.0010403005 | H26: 0 | I26: =$H26/$AI26 -> 0 | J26: 4643.673 | K26: =$J26/$AI26 -> 0.037582195 | M26: =$L26/$AI26 -> 0 | O26: =$N26/$AI26 -> 0 | P26: 185.55 | Q26: =$P26/$AI26 -> 0.0015016941 | R26: 1208.245 | S26: =$R26/$AI26 -> 0.0097785737 | U26: =$T26/$AI26 -> 0 | W26: =$V26/$AI26 -> 0 | X26: 385.9 | Y26: =$X26/$AI26 -> 0.0031231676 | Z26: 872.497 | AA26: =$Z26/$AI26 -> 0.0070612965 | AB26: 11074.405 | AC26: =$AB26/AI26 -> 0.089627423 | AD26: 69758.571 | AE26: =$AD26/$AI26 -> 0.56457037 | AF26: -107646.38 | AG26: -15914.072 | AH26: =SUM(AF26,AG26) -> -123560.45 | AI26: =((AF26+AG26)*-1) -> 123560.45 | AJ26: =AI26/($AI$224) -> 0.0094291768 | AK26: =AJ26*($G$260+$G$313-$B$406) -> 16654.984 | AL26: 28062.578 | AM26: =AL26/AL$224 -> 0.005955784 | AN26: =(AM26*$B$406) -> 8097.3945 | AO26: =AN26+AK26 -> 24752.378 | AP26: =$AO26/$AI26 -> 0.20032606 | AQ26: =AB26+AD26+AH26 -> -42727.477 | AR26: =AQ26+AO26 -> -17975.099 | AS26: =AR26/AI26 -> -0.14547615
A27: [ BZC ] - BAZAR 4 | B27: 0 | C27: =$B27/$AI27 -> 0 | D27: 1200 | E27: =$D27/$AI27 -> 0.024557499 | F27: 0 | G27: =$F27/$AI27 -> 0 | H27: 0 | I27: =$H27/$AI27 -> 0 | J27: 2917.646 | K27: =$J27/$AI27 -> 0.059708408 | M27: =$L27/$AI27 -> 0 | O27: =$N27/$AI27 -> 0 | P27: 129.93 | Q27: =$P27/$AI27 -> 0.0026589633 | R27: 309.567 | S27: =$R27/$AI27 -> 0.0063351595 | U27: =$T27/$AI27 -> 0 | W27: =$V27/$AI27 -> 0 | X27: 184.93 | Y27: =$X27/$AI27 -> 0.0037845153 | Z27: 63.136 | AA27: =$Z27/$AI27 -> 0.0012920519 | AB27: 4805.209 | AC27: =$AB27/AI27 -> 0.098336598 | AD27: 28294.648 | AE27: =$AD27/$AI27 -> 0.57903817 | AF27: -43041.202 | AG27: -5823.708 | AH27: =SUM(AF27,AG27) -> -48864.91 | AI27: =((AF27+AG27)*-1) -> 48864.91 | AJ27: =AI27/($AI$224) -> 0.0037289915 | AK27: =AJ27*($G$260+$G$313-$B$406) -> 6586.608 | AL27: 10395.796 | AM27: =AL27/AL$224 -> 0.0022063232 | AN27: =(AM27*$B$406) -> 2999.6839 | AO27: =AN27+AK27 -> 9586.292 | AP27: =$AO27/$AI27 -> 0.19617947 | AQ27: =AB27+AD27+AH27 -> -15765.053 | AR27: =AQ27+AO27 -> -6178.761 | AS27: =AR27/AI27 -> -0.12644577 | AU27: TIENDAS NUEVAS
A28: [ BZD ] - BAZAR 2 | B28: 0 | C28: =$B28/$AI28 -> 0 | D28: 1200 | E28: =$D28/$AI28 -> 0.010757121 | F28: 0 | G28: =$F28/$AI28 -> 0 | H28: 0 | I28: =$H28/$AI28 -> 0 | J28: 3609.041 | K28: =$J28/$AI28 -> 0.03235241 | M28: =$L28/$AI28 -> 0 | O28: =$N28/$AI28 -> 0 | P28: 171.98 | Q28: =$P28/$AI28 -> 0.0015416748 | R28: 102.433 | S28: =$R28/$AI28 -> 0.00091823683 | T28: 6.57 | U28: =$T28/$AI28 -> 5.8895239e-05 | W28: =$V28/$AI28 -> 0 | X28: 209.17 | Y28: =$X28/$AI28 -> 0.0018750559 | Z28: 122.607 | AA28: =$Z28/$AI28 -> 0.001099082 | AB28: 5421.801 | AC28: =$AB28/AI28 -> 0.048602476 | AD28: 65230.391 | AE28: =$AD28/$AI28 -> 0.58474269 | AF28: -97801.734 | AG28: -13752.275 | AH28: =SUM(AF28,AG28) -> -111554.01 | AI28: =((AF28+AG28)*-1) -> 111554.01 | AJ28: =AI28/($AI$224) -> 0.008512938 | AK28: =AJ28*($G$260+$G$313-$B$406) -> 15036.609 | AL28: 23517.646 | AM28: =AL28/AL$224 -> 0.0049912028 | AN28: =(AM28*$B$406) -> 6785.9644 | AO28: =AN28+AK28 -> 21822.573 | AP28: =$AO28/$AI28 -> 0.19562339 | AQ28: =AB28+AD28+AH28 -> -40901.817 | AR28: =AQ28+AO28 -> -19079.244 | AS28: =AR28/AI28 -> -0.17103145 | AU28: [ ADS - BQT ] - AEDOS BARQUISIMETO
A29: [ BZT ] - BAZAR 3 | B29: 0 | C29: =$B29/$AI29 -> 0 | D29: 1000 | E29: =$D29/$AI29 -> 0.028736 | F29: 0 | G29: =$F29/$AI29 -> 0 | H29: 0 | I29: =$H29/$AI29 -> 0 | J29: 2738.454 | K29: =$J29/$AI29 -> 0.078692215 | M29: =$L29/$AI29 -> 0 | O29: =$N29/$AI29 -> 0 | P29: 114.42 | Q29: =$P29/$AI29 -> 0.0032879732 | R29: 75.61 | S29: =$R29/$AI29 -> 0.002172729 | U29: =$T29/$AI29 -> 0 | W29: =$V29/$AI29 -> 0 | X29: 186 | Y29: =$X29/$AI29 -> 0.0053448961 | Z29: 27.424 | AA29: =$Z29/$AI29 -> 0.00078805608 | AB29: 4141.908 | AC29: =$AB29/AI29 -> 0.11902187 | AD29: 18863.316 | AE29: =$AD29/$AI29 -> 0.54205626 | AF29: -30700.528 | AG29: -4099.026 | AH29: =SUM(AF29,AG29) -> -34799.554 | AI29: =((AF29+AG29)*-1) -> 34799.554 | AJ29: =AI29/($AI$224) -> 0.0026556324 | AK29: =AJ29*($G$260+$G$313-$B$406) -> 4690.708 | AL29: 8313.2578 | AM29: =AL29/AL$224 -> 0.0017643414 | AN29: =(AM29*$B$406) -> 2398.7721 | AO29: =AN29+AK29 -> 7089.48 | AP29: =$AO29/$AI29 -> 0.2037233 | AQ29: =AB29+AD29+AH29 -> -11794.33 | AR29: =AQ29+AO29 -> -4704.85 | AS29: =AR29/AI29 -> -0.13519857 | AU29: [ ARY ] - AROA YARACUY
A30: [ BZU ] - BAZAR 1 | B30: 0 | C30: =$B30/$AI30 -> 0 | D30: 1200 | E30: =$D30/$AI30 -> 0.020241401 | F30: 0 | G30: =$F30/$AI30 -> 0 | H30: 0 | I30: =$H30/$AI30 -> 0 | J30: 2653.566 | K30: =$J30/$AI30 -> 0.04475991 | M30: =$L30/$AI30 -> 0 | O30: =$N30/$AI30 -> 0 | P30: 107.1 | Q30: =$P30/$AI30 -> 0.001806545 | R30: 93.32 | S30: =$R30/$AI30 -> 0.0015741063 | T30: 6.57 | U30: =$T30/$AI30 -> 0.00011082167 | W30: =$V30/$AI30 -> 0 | X30: 186.79 | Y30: =$X30/$AI30 -> 0.0031507427 | Z30: 144.973 | AA30: =$Z30/$AI30 -> 0.0024453805 | AB30: 4392.319 | AC30: =$AB30/AI30 -> 0.074088907 | AD30: 33010.969 | AE30: =$AD30/$AI30 -> 0.55682354 | AF30: -52116.931 | AG30: -7167.504 | AH30: =SUM(AF30,AG30) -> -59284.435 | AI30: =((AF30+AG30)*-1) -> 59284.435 | AJ30: =AI30/($AI$224) -> 0.0045241289 | AK30: =AJ30*($G$260+$G$313-$B$406) -> 7991.0786 | AL30: 14567.642 | AM30: =AL30/AL$224 -> 0.0030917233 | AN30: =(AM30*$B$406) -> 4203.4607 | AO30: =AN30+AK30 -> 12194.539 | AP30: =$AO30/$AI30 -> 0.20569546 | AQ30: =AB30+AD30+AH30 -> -21881.147 | AR30: =AQ30+AO30 -> -9686.6077 | AS30: =AR30/AI30 -> -0.16339209 | AU30: [ BLS ] - BAILADORES
A31: [ CAG ] - CAGUA | B31: 0 | C31: =$B31/$AI31 -> 0 | D31: 700 | E31: =$D31/$AI31 -> 0.0095288515 | F31: 149.51 | G31: =$F31/$AI31 -> 0.0020352266 | H31: 0 | I31: =$H31/$AI31 -> 0 | J31: 3383.434 | K31: =$J31/$AI31 -> 0.046057486 | M31: =$L31/$AI31 -> 0 | O31: =$N31/$AI31 -> 0 | P31: 85.36 | Q31: =$P31/$AI31 -> 0.0011619754 | R31: 1287.054 | S31: =$R31/$AI31 -> 0.017520209 | U31: =$T31/$AI31 -> 0 | W31: =$V31/$AI31 -> 0 | X31: 191.87 | Y31: =$X31/$AI31 -> 0.0026118582 | Z31: 78.073 | AA31: =$Z31/$AI31 -> 0.00106278 | AB31: 5875.301 | AC31: =$AB31/AI31 -> 0.079978387 | AD31: 35349.549 | AE31: =$AD31/$AI31 -> 0.48120086 | AF31: -64164.724 | AG31: -9296.385 | AH31: =SUM(AF31,AG31) -> -73461.109 | AI31: =((AF31+AG31)*-1) -> 73461.109 | AJ31: =AI31/($AI$224) -> 0.0056059829 | AK31: =AJ31*($G$260+$G$313-$B$406) -> 9901.9835 | AL31: 24410.196 | AM31: =AL31/AL$224 -> 0.0051806308 | AN31: =(AM31*$B$406) -> 7043.5079 | AO31: =AN31+AK31 -> 16945.491 | AP31: =$AO31/$AI31 -> 0.23067296 | AQ31: =AB31+AD31+AH31 -> -32236.259 | AR31: =AQ31+AO31 -> -15290.768 | AS31: =AR31/AI31 -> -0.20814779 | AU31: [ TVR ] - TOVAR MERIDA
A32: [ CAT ] - CATIA | B32: 0 | C32: =$B32/$AI32 -> 0 | D32: 2600 | E32: =$D32/$AI32 -> 0.015340892 | F32: 0 | G32: =$F32/$AI32 -> 0 | H32: 0 | I32: =$H32/$AI32 -> 0 | J32: 11218.025 | K32: =$J32/$AI32 -> 0.066190197 | M32: =$L32/$AI32 -> 0 | N32: 228.45 | O32: =$N32/$AI32 -> 0.0013479334 | P32: 150.84 | Q32: =$P32/$AI32 -> 0.00089000776 | R32: 1163.745 | S32: =$R32/$AI32 -> 0.0068664948 | U32: =$T32/$AI32 -> 0 | W32: =$V32/$AI32 -> 0 | X32: 352.564 | Y32: =$X32/$AI32 -> 0.0020802486 | Z32: 171.075 | AA32: =$Z32/$AI32 -> 0.0010094012 | AB32: 15884.699 | AC32: =$AB32/AI32 -> 0.093725175 | AD32: 84387.513 | AE32: =$AD32/$AI32 -> 0.49791528 | AF32: -147246.17 | AG32: -22235.497 | AH32: =SUM(AF32,AG32) -> -169481.67 | AI32: =((AF32+AG32)*-1) -> 169481.67 | AJ32: =AI32/($AI$224) -> 0.012933528 | AK32: =AJ32*($G$260+$G$313-$B$406) -> 22844.805 | AL32: 66747.561 | AM32: =AL32/AL$224 -> 0.014165985 | AN32: =(AM32*$B$406) -> 19259.861 | AO32: =AN32+AK32 -> 42104.665 | AP32: =$AO32/$AI32 -> 0.24843197 | AQ32: =AB32+AD32+AH32 -> -69209.456 | AR32: =AQ32+AO32 -> -27104.791 | AS32: =AR32/AI32 -> -0.15992757 | AU32: [ ABM ] - AV BOLIVAR DE MATURIN
A33: [ CBM ] - CABIMAS | B33: 0 | C33: =$B33/$AI33 -> 0 | D33: 1000 | E33: =$D33/$AI33 -> 0.011708942 | F33: 50.28 | G33: =$F33/$AI33 -> 0.0005887256 | H33: 0 | I33: =$H33/$AI33 -> 0 | J33: 3940.957 | K33: =$J33/$AI33 -> 0.046144437 | M33: =$L33/$AI33 -> 0 | O33: =$N33/$AI33 -> 0 | P33: 183.4 | Q33: =$P33/$AI33 -> 0.00214742 | R33: 2068.952 | S33: =$R33/$AI33 -> 0.024225239 | U33: =$T33/$AI33 -> 0 | W33: =$V33/$AI33 -> 0 | X33: 114.69 | Y33: =$X33/$AI33 -> 0.0013428986 | Z33: 16.534 | AA33: =$Z33/$AI33 -> 0.00019359565 | AB33: 7374.813 | AC33: =$AB33/AI33 -> 0.086351258 | AD33: 43333.13 | AE33: =$AD33/$AI33 -> 0.5073851 | AF33: -74464.669 | AG33: -10940.144 | AH33: =SUM(AF33,AG33) -> -85404.813 | AI33: =((AF33+AG33)*-1) -> 85404.813 | AJ33: =AI33/($AI$224) -> 0.0065174339 | AK33: =AJ33*($G$260+$G$313-$B$406) -> 11511.901 | AL33: 29725.609 | AM33: =AL33/AL$224 -> 0.0063087327 | AN33: =(AM33*$B$406) -> 8577.2583 | AO33: =AN33+AK33 -> 20089.16 | AP33: =$AO33/$AI33 -> 0.23522281 | AQ33: =AB33+AD33+AH33 -> -34696.87 | AR33: =AQ33+AO33 -> -14607.71 | AS33: =AR33/AI33 -> -0.17104083
A34: [ CBQ ] - CHABASQUEN | B34: 0 | C34: =$B34/$AI34 -> 0 | D34: 500 | E34: =$D34/$AI34 -> 0.019421878 | F34: 45.47 | G34: =$F34/$AI34 -> 0.0017662256 | H34: 0 | I34: =$H34/$AI34 -> 0 | J34: 2559.083 | K34: =$J34/$AI34 -> 0.099404397 | M34: =$L34/$AI34 -> 0 | O34: =$N34/$AI34 -> 0 | P34: 22.67 | Q34: =$P34/$AI34 -> 0.00088058796 | R34: 1804.946 | S34: =$R34/$AI34 -> 0.070110883 | U34: =$T34/$AI34 -> 0 | W34: =$V34/$AI34 -> 0 | X34: 93.04 | Y34: =$X34/$AI34 -> 0.0036140231 | Z34: 179.762 | AA34: =$Z34/$AI34 -> 0.0069826314 | AB34: 5204.971 | AC34: =$AB34/AI34 -> 0.20218063 | AD34: 12712.48 | AE34: =$AD34/$AI34 -> 0.49380048 | AF34: -22404.081 | AG34: -3340.082 | AH34: =SUM(AF34,AG34) -> -25744.163 | AI34: =((AF34+AG34)*-1) -> 25744.163 | AJ34: =AI34/($AI$224) -> 0.0019645951 | AK34: =AJ34*($G$260+$G$313-$B$406) -> 3470.112 | AL34: 8589.9372 | AM34: =AL34/AL$224 -> 0.0018230617 | AN34: =(AM34*$B$406) -> 2478.6073 | AO34: =AN34+AK34 -> 5948.7193 | AP34: =$AO34/$AI34 -> 0.2310706 | AQ34: =AB34+AD34+AH34 -> -7826.712 | AR34: =AQ34+AO34 -> -1877.9927 | AS34: =AR34/AI34 -> -0.072948291
A35: [ CBR ] - CABUDARE | B35: 0 | C35: =$B35/$AI35 -> 0 | D35: 600 | E35: =$D35/$AI35 -> 0.014626037 | F35: 70 | G35: =$F35/$AI35 -> 0.001706371 | H35: 0 | I35: =$H35/$AI35 -> 0 | J35: 3951.349 | K35: =$J35/$AI35 -> 0.096320962 | M35: =$L35/$AI35 -> 0 | O35: =$N35/$AI35 -> 0 | P35: 26.68 | Q35: =$P35/$AI35 -> 0.00065037112 | R35: 629.403 | S35: =$R35/$AI35 -> 0.015342786 | U35: =$T35/$AI35 -> 0 | W35: =$V35/$AI35 -> 0 | X35: 45.9 | Y35: =$X35/$AI35 -> 0.0011188918 | Z35: 93.4 | AA35: =$Z35/$AI35 -> 0.0022767864 | AB35: 5416.732 | AC35: =$AB35/AI35 -> 0.13204221 | AD35: 18104.009 | AE35: =$AD35/$AI35 -> 0.44131651 | AF35: -36012.324 | AG35: -5010.408 | AH35: =SUM(AF35,AG35) -> -41022.732 | AI35: =((AF35+AG35)*-1) -> 41022.732 | AJ35: =AI35/($AI$224) -> 0.0031305372 | AK35: =AJ35*($G$260+$G$313-$B$406) -> 5529.5437 | AL35: 15263.332 | AM35: =AL35/AL$224 -> 0.0032393712 | AN35: =(AM35*$B$406) -> 4404.2004 | AO35: =AN35+AK35 -> 9933.7442 | AP35: =$AO35/$AI35 -> 0.24215218 | AQ35: =AB35+AD35+AH35 -> -17501.991 | AR35: =AQ35+AO35 -> -7568.2468 | AS35: =AR35/AI35 -> -0.1844891
A36: [ CBV ] - CIUDAD BOLIVAR | B36: 0 | C36: =$B36/$AI36 -> 0 | D36: 1007 | E36: =$D36/$AI36 -> 0.013376157 | F36: 24.51 | G36: =$F36/$AI36 -> 0.00032557061 | H36: 0 | I36: =$H36/$AI36 -> 0 | J36: 6370.228 | K36: =$J36/$AI36 -> 0.084616852 | M36: =$L36/$AI36 -> 0 | N36: 291.2 | O36: =$N36/$AI36 -> 0.0038680605 | P36: 161.59 | Q36: =$P36/$AI36 -> 0.0021464282 | R36: 1725.395 | S36: =$R36/$AI36 -> 0.022918723 | U36: =$T36/$AI36 -> 0 | W36: =$V36/$AI36 -> 0 | X36: 123.68 | Y36: =$X36/$AI36 -> 0.0016428631 | Z36: 28.608 | AA36: =$Z36/$AI36 -> 0.00038000507 | AB36: 9732.211 | AC36: =$AB36/AI36 -> 0.12927466 | AD36: 36033.337 | AE36: =$AD36/$AI36 -> 0.47863711 | AF36: -65915.319 | AG36: -9367.888 | AH36: =SUM(AF36,AG36) -> -75283.207 | AI36: =((AF36+AG36)*-1) -> 75283.207 | AJ36: =AI36/($AI$224) -> 0.0057450313 | AK36: =AJ36*($G$260+$G$313-$B$406) -> 10147.588 | AL36: 27392.171 | AM36: =AL36/AL$224 -> 0.005813502 | AN36: =(AM36*$B$406) -> 7903.9501 | AO36: =AN36+AK36 -> 18051.538 | AP36: =$AO36/$AI36 -> 0.23978174 | AQ36: =AB36+AD36+AH36 -> -29517.659 | AR36: =AQ36+AO36 -> -11466.121 | AS36: =AR36/AI36 -> -0.15230649
A37: [ CCA ] - CENTRO COMERCIAL AVIADORES | B37: 0 | C37: =$B37/$AI37 -> 0 | D37: 2212.97 | E37: =$D37/$AI37 -> 0.046472405 | F37: 11.43 | G37: =$F37/$AI37 -> 0.00024003018 | H37: 0 | I37: =$H37/$AI37 -> 0 | J37: 3744.306 | K37: =$J37/$AI37 -> 0.078630485 | M37: =$L37/$AI37 -> 0 | N37: 29.14 | O37: =$N37/$AI37 -> 0.00061194046 | P37: 482.9 | Q37: =$P37/$AI37 -> 0.010140908 | R37: 153.692 | S37: =$R37/$AI37 -> 0.0032275344 | U37: =$T37/$AI37 -> 0 | W37: =$V37/$AI37 -> 0 | X37: 976.26 | Y37: =$X37/$AI37 -> 0.020501475 | Z37: 279.311 | AA37: =$Z37/$AI37 -> 0.0058655354 | AB37: 7890.009 | AC37: =$AB37/AI37 -> 0.16569031 | AD37: 20686.388 | AE37: =$AD37/$AI37 -> 0.43441447 | AF37: -41597.093 | AG37: -6021.919 | AH37: =SUM(AF37,AG37) -> -47619.012 | AI37: =((AF37+AG37)*-1) -> 47619.012 | AJ37: =AI37/($AI$224) -> 0.0036339142 | AK37: =AJ37*($G$260+$G$313-$B$406) -> 6418.6707 | AL37: 16151.289 | AM37: =AL37/AL$224 -> 0.0034278242 | AN37: =(AM37*$B$406) -> 4660.4184 | AO37: =AN37+AK37 -> 11079.089 | AP37: =$AO37/$AI37 -> 0.23266105 | AQ37: =AB37+AD37+AH37 -> -19042.615 | AR37: =AQ37+AO37 -> -7963.5259 | AS37: =AR37/AI37 -> -0.16723417
A38: [ CCB ] - CALLE CAMEJO BARINAS | B38: 0 | C38: =$B38/$AI38 -> 0 | D38: 575 | E38: =$D38/$AI38 -> 0.012508857 | F38: 67.5 | G38: =$F38/$AI38 -> 0.0014684311 | H38: 0 | I38: =$H38/$AI38 -> 0 | J38: 2136.507 | K38: =$J38/$AI38 -> 0.046478715 | M38: =$L38/$AI38 -> 0 | O38: =$N38/$AI38 -> 0 | Q38: =$P38/$AI38 -> 0 | R38: 714.853 | S38: =$R38/$AI38 -> 0.015551294 | U38: =$T38/$AI38 -> 0 | W38: =$V38/$AI38 -> 0 | X38: 69.65 | Y38: =$X38/$AI38 -> 0.0015152033 | Z38: 112.768 | AA38: =$Z38/$AI38 -> 0.0024532154 | AB38: 3676.278 | AC38: =$AB38/AI38 -> 0.079975717 | AD38: 25348.269 | AE38: =$AD38/$AI38 -> 0.55143979 | AF38: -40119.566 | AG38: -5847.862 | AH38: =SUM(AF38,AG38) -> -45967.428 | AI38: =((AF38+AG38)*-1) -> 45967.428 | AJ38: =AI38/($AI$224) -> 0.0035078781 | AK38: =AJ38*($G$260+$G$313-$B$406) -> 6196.0501 | AL38: 14810.77 | AM38: =AL38/AL$224 -> 0.0031433229 | AN38: =(AM38*$B$406) -> 4273.6147 | AO38: =AN38+AK38 -> 10469.665 | AP38: =$AO38/$AI38 -> 0.22776268 | AQ38: =AB38+AD38+AH38 -> -16942.881 | AR38: =AQ38+AO38 -> -6473.2162 | AS38: =AR38/AI38 -> -0.14082181
A39: [ CCM ] - CENTRO COMERCIAL METROCENTER | B39: 0 | C39: =$B39/$AI39 -> 0 | D39: 1200 | E39: =$D39/$AI39 -> 0.01808444 | F39: 0 | G39: =$F39/$AI39 -> 0 | H39: 0 | I39: =$H39/$AI39 -> 0 | J39: 2388.414 | K39: =$J39/$AI39 -> 0.035994275 | M39: =$L39/$AI39 -> 0 | O39: =$N39/$AI39 -> 0 | P39: 126.27 | Q39: =$P39/$AI39 -> 0.0019029352 | R39: 731.877 | S39: =$R39/$AI39 -> 0.011029655 | U39: =$T39/$AI39 -> 0 | W39: =$V39/$AI39 -> 0 | X39: 356.43 | Y39: =$X39/$AI39 -> 0.0053715309 | Z39: 516.138 | AA39: =$Z39/$AI39 -> 0.007778389 | AB39: 5319.129 | AC39: =$AB39/AI39 -> 0.080161226 | AD39: 34707.77 | AE39: =$AD39/$AI39 -> 0.52305883 | AF39: -59060.347 | AG39: -7295.038 | AH39: =SUM(AF39,AG39) -> -66355.385 | AI39: =((AF39+AG39)*-1) -> 66355.385 | AJ39: =AI39/($AI$224) -> 0.0050637291 | AK39: =AJ39*($G$260+$G$313-$B$406) -> 8944.1874 | AL39: 27201.271 | AM39: =AL39/AL$224 -> 0.0057729868 | AN39: =(AM39*$B$406) -> 7848.8663 | AO39: =AN39+AK39 -> 16793.054 | AP39: =$AO39/$AI39 -> 0.25307748 | AQ39: =AB39+AD39+AH39 -> -26328.486 | AR39: =AQ39+AO39 -> -9535.4323 | AS39: =AR39/AI39 -> -0.14370246
A40: [ CCO ] - CAICARA DEL ORINOCO | B40: 0 | C40: =$B40/$AI40 -> 0 | D40: 600 | E40: =$D40/$AI40 -> 0.013295816 | F40: 0 | G40: =$F40/$AI40 -> 0 | H40: 0 | I40: =$H40/$AI40 -> 0 | J40: 3274.394 | K40: =$J40/$AI40 -> 0.072559566 | M40: =$L40/$AI40 -> 0 | O40: =$N40/$AI40 -> 0 | P40: 83.51 | Q40: =$P40/$AI40 -> 0.001850556 | R40: 1135.959 | S40: =$R40/$AI40 -> 0.025172503 | U40: =$T40/$AI40 -> 0 | W40: =$V40/$AI40 -> 0 | X40: 69.7 | Y40: =$X40/$AI40 -> 0.0015445306 | Z40: 42.725 | AA40: =$Z40/$AI40 -> 0.00094677288 | AB40: 5206.288 | AC40: =$AB40/AI40 -> 0.11536974 | AD40: 22041.84 | AE40: =$AD40/$AI40 -> 0.48844041 | AF40: -39411.242 | AG40: -5715.737 | AH40: =SUM(AF40,AG40) -> -45126.979 | AI40: =((AF40+AG40)*-1) -> 45126.979 | AJ40: =AI40/($AI$224) -> 0.0034437415 | AK40: =AJ40*($G$260+$G$313-$B$406) -> 6082.7642 | AL40: 17926.354 | AM40: =AL40/AL$224 -> 0.0038045504 | AN40: =(AM40*$B$406) -> 5172.6097 | AO40: =AN40+AK40 -> 11255.374 | AP40: =$AO40/$AI40 -> 0.24941563 | AQ40: =AB40+AD40+AH40 -> -17878.851 | AR40: =AQ40+AO40 -> -6623.4772 | AS40: =AR40/AI40 -> -0.14677422
...

Sheet Sr. Wilson 4
B4: Total general | C4: Centro de Costo | D4: Total Ingresos | E4: Total Costos | F4: Total Gastos | G4: Monto Ingresos Bs | H4: Factor de ingresos en bs | I4: Gasto Aplicado por Venta | J4: % impacto sobre ingresos generales | K4: Gasto aplicado | L4: Gasto Aplicado Factor Ingreso Bs | M4: Total General CC | N4: Resultado - Gastos Distribuidos
